Workbook
Name Slicer_Gender: #N/A
Name Slicer_Generation: #N/A
Name Slicer_Product_Category: #N/A

Sheet Sheet1
A3: Sum of Total Sales | B3: Generation
A4: Product Category | B4: Adult | C4: Senior | D4: Young Adult | E4: Grand Total
A5: Beauty | B5: 70230 | C5: 31885 | D5: 41400 | E5: 143515
A6: Clothing | B6: 63310 | C6: 46120 | D6: 46150 | E6: 155580
A7: Electronics | B7: 65995 | C7: 55305 | D7: 35605 | E7: 156905
A8: Grand Total | B8: 199535 | C8: 133310 | D8: 123155 | E8: 456000

Sheet retail_sales_dataset
A1: Transaction ID | B1: Day | C1: Month | D1: Year | E1: Day | F1: Month | G1: Date | H1: Customer ID | I1: Gender | J1: Generation | K1: Age | L1: Product Category | M1: Quantity | N1: Price per Unit | O1: Total Sales | P1: Commission 2023 | Q1: Commission 2024
A2: 650 | B2: =DAY(G2) -> 1 | C2: =MONTH(G2) -> 1 | D2: =YEAR(G2) -> 2024 | E2: =TEXT(G2,"dddd") -> Monday | F2: =TEXT(G2,"mmm") -> Jan | G2: 45292 | H2: CUST650 | I2: Male | J2: {=_xlfn.IFS(K2<30,"Young Adult",K2<=50,"Adult",K2>50,"Senior")} -> Senior | K2: 55 | L2: Electronics | M2: 1 | N2: 30 | O2: =M2 * N2 -> 30 | P2: =O2*$S$3 -> 0.45 | Q2: =O2*$S$4 -> 0.6 | S2: Rate %
A3: 211 | B3: =DAY(G3) -> 1 | C3: =MONTH(G3) -> 1 | D3: =YEAR(G3) -> 2024 | E3: =TEXT(G3,"dddd") -> Monday | F3: =TEXT(G3,"mmm") -> Jan | G3: 45292 | H3: CUST211 | I3: Male | J3: {=_xlfn.IFS(K3<30,"Young Adult",K3<=50,"Adult",K3>50,"Senior")} -> Adult | K3: 42 | L3: Beauty | M3: 3 | N3: 500 | O3: =M3 * N3 -> 1500 | P3: =O3*$S$3 -> 22.5 | Q3: =O3*$S$4 -> 30 | S3: 0.015 | W3: {=_xlfn.UNIQUE(L:L)} -> Product Category
A4: 857 | B4: =DAY(G4) -> 31 | C4: =MONTH(G4) -> 12 | D4: =YEAR(G4) -> 2023 | E4: =TEXT(G4,"dddd") -> Sunday | F4: =TEXT(G4,"mmm") -> Dec | G4: 45291 | H4: CUST857 | I4: Male | J4: {=_xlfn.IFS(K4<30,"Young Adult",K4<=50,"Adult",K4>50,"Senior")} -> Senior | K4: 60 | L4: Electronics | M4: 2 | N4: 25 | O4: =M4 * N4 -> 50 | P4: =O4*$S$3 -> 0.75 | Q4: =O4*$S$4 -> 1 | S4: 0.02 | W4: Electronics
A5: 233 | B5: =DAY(G5) -> 29 | C5: =MONTH(G5) -> 12 | D5: =YEAR(G5) -> 2023 | E5: =TEXT(G5,"dddd") -> Friday | F5: =TEXT(G5,"mmm") -> Dec | G5: 45289 | H5: CUST233 | I5: Female | J5: {=_xlfn.IFS(K5<30,"Young Adult",K5<=50,"Adult",K5>50,"Senior")} -> Senior | K5: 51 | L5: Beauty | M5: 2 | N5: 300 | O5: =M5 * N5 -> 600 | P5: =O5*$S$3 -> 9 | Q5: =O5*$S$4 -> 12 | W5: Beauty
A6: 520 | B6: =DAY(G6) -> 29 | C6: =MONTH(G6) -> 12 | D6: =YEAR(G6) -> 2023 | E6: =TEXT(G6,"dddd") -> Friday | F6: =TEXT(G6,"mmm") -> Dec | G6: 45289 | H6: CUST520 | I6: Female | J6: {=_xlfn.IFS(K6<30,"Young Adult",K6<=50,"Adult",K6>50,"Senior")} -> Adult | K6: 49 | L6: Electronics | M6: 4 | N6: 25 | O6: =M6 * N6 -> 100 | P6: =O6*$S$3 -> 1.5 | Q6: =O6*$S$4 -> 2 | W6: Clothing
A7: 908 | B7: =DAY(G7) -> 29 | C7: =MONTH(G7) -> 12 | D7: =YEAR(G7) -> 2023 | E7: =TEXT(G7,"dddd") -> Friday | F7: =TEXT(G7,"mmm") -> Dec | G7: 45289 | H7: CUST908 | I7: Male | J7: {=_xlfn.IFS(K7<30,"Young Adult",K7<=50,"Adult",K7>50,"Senior")} -> Adult | K7: 46 | L7: Beauty | M7: 4 | N7: 300 | O7: =M7 * N7 -> 1200 | P7: =O7*$S$3 -> 18 | Q7: =O7*$S$4 -> 24 | W7: 0
A8: 805 | B8: =DAY(G8) -> 29 | C8: =MONTH(G8) -> 12 | D8: =YEAR(G8) -> 2023 | E8: =TEXT(G8,"dddd") -> Friday | F8: =TEXT(G8,"mmm") -> Dec | G8: 45289 | H8: CUST805 | I8: Female | J8: {=_xlfn.IFS(K8<30,"Young Adult",K8<=50,"Adult",K8>50,"Senior")} -> Adult | K8: 30 | L8: Beauty | M8: 3 | N8: 500 | O8: =M8 * N8 -> 1500 | P8: =O8*$S$3 -> 22.5 | Q8: =O8*$S$4 -> 30 | R8: Column1 | S8: Column2 | T8: Quantity | U8: Quantity2
A9: 429 | B9: =DAY(G9) -> 28 | C9: =MONTH(G9) -> 12 | D9: =YEAR(G9) -> 2023 | E9: =TEXT(G9,"dddd") -> Thursday | F9: =TEXT(G9,"mmm") -> Dec | G9: 45288 | H9: CUST429 | I9: Male | J9: {=_xlfn.IFS(K9<30,"Young Adult",K9<=50,"Adult",K9>50,"Senior")} -> Senior | K9: 64 | L9: Electronics | M9: 2 | N9: 25 | O9: =M9 * N9 -> 50 | P9: =O9*$S$3 -> 0.75 | Q9: =O9*$S$4 -> 1 | S9: Overall Sales | T9: Female | U9: Male
A10: 664 | B10: =DAY(G10) -> 28 | C10: =MONTH(G10) -> 12 | D10: =YEAR(G10) -> 2023 | E10: =TEXT(G10,"dddd") -> Thursday | F10: =TEXT(G10,"mmm") -> Dec | G10: 45288 | H10: CUST664 | I10: Female | J10: {=_xlfn.IFS(K10<30,"Young Adult",K10<=50,"Adult",K10>50,"Senior")} -> Adult | K10: 44 | L10: Clothing | M10: 4 | N10: 500 | O10: =M10 * N10 -> 2000 | P10: =O10*$S$3 -> 30 | Q10: =O10*$S$4 -> 40 | R10: All products | S10: =SUM(O:O) -> 456000 | T10: =SUMIFS(M2:M1001,I2:I1001,"female") -> 1298 | U10: =SUMIF(I2:I1001,"male",M2:M1001) -> 1216
A11: 989 | B11: =DAY(G11) -> 28 | C11: =MONTH(G11) -> 12 | D11: =YEAR(G11) -> 2023 | E11: =TEXT(G11,"dddd") -> Thursday | F11: =TEXT(G11,"mmm") -> Dec | G11: 45288 | H11: CUST989 | I11: Female | J11: {=_xlfn.IFS(K11<30,"Young Adult",K11<=50,"Adult",K11>50,"Senior")} -> Adult | K11: 44 | L11: Electronics | M11: 1 | N11: 25 | O11: =M11 * N11 -> 25 | P11: =O11*$S$3 -> 0.375 | Q11: =O11*$S$4 -> 0.5 | R11: Beauty | S11: =SUMIF(L2:L1001,"Beauty",O2:O1001) -> 143515 | T11: =SUMIFS(M2:M1001,I2:I1001,"female",L2:L1001,"beauty") -> 418 | U11: =SUMIFS(M2:M1001,I2:I1001,"male",L2:L1001,"beauty") -> 353
A12: 386 | B12: =DAY(G12) -> 27 | C12: =MONTH(G12) -> 12 | D12: =YEAR(G12) -> 2023 | E12: =TEXT(G12,"dddd") -> Wednesday | F12: =TEXT(G12,"mmm") -> Dec | G12: 45287 | H12: CUST386 | I12: Female | J12: {=_xlfn.IFS(K12<30,"Young Adult",K12<=50,"Adult",K12>50,"Senior")} -> Senior | K12: 54 | L12: Electronics | M12: 2 | N12: 300 | O12: =M12 * N12 -> 600 | P12: =O12*$S$3 -> 9 | Q12: =O12*$S$4 -> 12 | R12: Clothing | S12: =SUMIF(L2:L1001,"Clothing",O2:O1001) -> 155580 | T12: =SUMIFS(M2:M1001,I2:I1001,"female",L2:L1001,"clothing") -> 441 | U12: =SUMIFS(M2:M1001,I2:I1001,"male",L2:L1001,"clothing") -> 453
A13: 62 | B13: =DAY(G13) -> 27 | C13: =MONTH(G13) -> 12 | D13: =YEAR(G13) -> 2023 | E13: =TEXT(G13,"dddd") -> Wednesday | F13: =TEXT(G13,"mmm") -> Dec | G13: 45287 | H13: CUST062 | I13: Male | J13: {=_xlfn.IFS(K13<30,"Young Adult",K13<=50,"Adult",K13>50,"Senior")} -> Young Adult | K13: 18 | L13: Beauty | M13: 2 | N13: 50 | O13: =M13 * N13 -> 100 | P13: =O13*$S$3 -> 1.5 | Q13: =O13*$S$4 -> 2 | R13: Electronics | S13: =SUMIF(L2:L1001,"Electronics",O2:O1001) -> 156905 | T13: =SUMIFS(M2:M1001,I2:I1001,"female",L2:L1001,"electronics") -> 439 | U13: =SUMIFS(M2:M1001,I2:I1001,"male",L2:L1001,"electronics") -> 410
A14: 25 | B14: =DAY(G14) -> 26 | C14: =MONTH(G14) -> 12 | D14: =YEAR(G14) -> 2023 | E14: =TEXT(G14,"dddd") -> Tuesday | F14: =TEXT(G14,"mmm") -> Dec | G14: 45286 | H14: CUST025 | I14: Female | J14: {=_xlfn.IFS(K14<30,"Young Adult",K14<=50,"Adult",K14>50,"Senior")} -> Senior | K14: 64 | L14: Beauty | M14: 1 | N14: 50 | O14: =M14 * N14 -> 50 | P14: =O14*$S$3 -> 0.75 | Q14: =O14*$S$4 -> 1
A15: 842 | B15: =DAY(G15) -> 26 | C15: =MONTH(G15) -> 12 | D15: =YEAR(G15) -> 2023 | E15: =TEXT(G15,"dddd") -> Tuesday | F15: =TEXT(G15,"mmm") -> Dec | G15: 45286 | H15: CUST842 | I15: Female | J15: {=_xlfn.IFS(K15<30,"Young Adult",K15<=50,"Adult",K15>50,"Senior")} -> Adult | K15: 47 | L15: Clothing | M15: 2 | N15: 300 | O15: =M15 * N15 -> 600 | P15: =O15*$S$3 -> 9 | Q15: =O15*$S$4 -> 12
A16: 472 | B16: =DAY(G16) -> 26 | C16: =MONTH(G16) -> 12 | D16: =YEAR(G16) -> 2023 | E16: =TEXT(G16,"dddd") -> Tuesday | F16: =TEXT(G16,"mmm") -> Dec | G16: 45286 | H16: CUST472 | I16: Female | J16: {=_xlfn.IFS(K16<30,"Young Adult",K16<=50,"Adult",K16>50,"Senior")} -> Adult | K16: 38 | L16: Beauty | M16: 3 | N16: 300 | O16: =M16 * N16 -> 900 | P16: =O16*$S$3 -> 13.5 | Q16: =O16*$S$4 -> 18 | R16: Column1 | S16: Column2
A17: 991 | B17: =DAY(G17) -> 26 | C17: =MONTH(G17) -> 12 | D17: =YEAR(G17) -> 2023 | E17: =TEXT(G17,"dddd") -> Tuesday | F17: =TEXT(G17,"mmm") -> Dec | G17: 45286 | H17: CUST991 | I17: Female | J17: {=_xlfn.IFS(K17<30,"Young Adult",K17<=50,"Adult",K17>50,"Senior")} -> Adult | K17: 34 | L17: Clothing | M17: 2 | N17: 50 | O17: =M17 * N17 -> 100 | P17: =O17*$S$3 -> 1.5 | Q17: =O17*$S$4 -> 2 | R17: Total Comm 2023 | S17: =SUM(P:P) -> 6840
A18: 82 | B18: =DAY(G18) -> 26 | C18: =MONTH(G18) -> 12 | D18: =YEAR(G18) -> 2023 | E18: =TEXT(G18,"dddd") -> Tuesday | F18: =TEXT(G18,"mmm") -> Dec | G18: 45286 | H18: CUST082 | I18: Female | J18: {=_xlfn.IFS(K18<30,"Young Adult",K18<=50,"Adult",K18>50,"Senior")} -> Adult | K18: 32 | L18: Beauty | M18: 4 | N18: 50 | O18: =M18 * N18 -> 200 | P18: =O18*$S$3 -> 3 | Q18: =O18*$S$4 -> 4 | R18: Total Comm 2024 | S18: =SUM(Q:Q) -> 9120
A19: 879 | B19: =DAY(G19) -> 26 | C19: =MONTH(G19) -> 12 | D19: =YEAR(G19) -> 2023 | E19: =TEXT(G19,"dddd") -> Tuesday | F19: =TEXT(G19,"mmm") -> Dec | G19: 45286 | H19: CUST879 | I19: Male | J19: {=_xlfn.IFS(K19<30,"Young Adult",K19<=50,"Adult",K19>50,"Senior")} -> Young Adult | K19: 23 | L19: Clothing | M19: 1 | N19: 30 | O19: =M19 * N19 -> 30 | P19: =O19*$S$3 -> 0.45 | Q19: =O19*$S$4 -> 0.6
A20: 757 | B20: =DAY(G20) -> 25 | C20: =MONTH(G20) -> 12 | D20: =YEAR(G20) -> 2023 | E20: =TEXT(G20,"dddd") -> Monday | F20: =TEXT(G20,"mmm") -> Dec | G20: 45285 | H20: CUST757 | I20: Female | J20: {=_xlfn.IFS(K20<30,"Young Adult",K20<=50,"Adult",K20>50,"Senior")} -> Adult | K20: 43 | L20: Electronics | M20: 4 | N20: 300 | O20: =M20 * N20 -> 1200 | P20: =O20*$S$3 -> 18 | Q20: =O20*$S$4 -> 24
A21: 34 | B21: =DAY(G21) -> 24 | C21: =MONTH(G21) -> 12 | D21: =YEAR(G21) -> 2023 | E21: =TEXT(G21,"dddd") -> Sunday | F21: =TEXT(G21,"mmm") -> Dec | G21: 45284 | H21: CUST034 | I21: Female | J21: {=_xlfn.IFS(K21<30,"Young Adult",K21<=50,"Adult",K21>50,"Senior")} -> Senior | K21: 51 | L21: Clothing | M21: 3 | N21: 50 | O21: =M21 * N21 -> 150 | P21: =O21*$S$3 -> 2.25 | Q21: =O21*$S$4 -> 3 | R21: Column1 | S21: Column2
A22: 916 | B22: =DAY(G22) -> 24 | C22: =MONTH(G22) -> 12 | D22: =YEAR(G22) -> 2023 | E22: =TEXT(G22,"dddd") -> Sunday | F22: =TEXT(G22,"mmm") -> Dec | G22: 45284 | H22: CUST916 | I22: Female | J22: {=_xlfn.IFS(K22<30,"Young Adult",K22<=50,"Adult",K22>50,"Senior")} -> Adult | K22: 32 | L22: Electronics | M22: 1 | N22: 50 | O22: =M22 * N22 -> 50 | P22: =O22*$S$3 -> 0.75 | Q22: =O22*$S$4 -> 1 | R22: Avg Comm 2023 | S22: =AVERAGE(P:P) -> 6.84
A23: 615 | B23: =DAY(G23) -> 23 | C23: =MONTH(G23) -> 12 | D23: =YEAR(G23) -> 2023 | E23: =TEXT(G23,"dddd") -> Saturday | F23: =TEXT(G23,"mmm") -> Dec | G23: 45283 | H23: CUST615 | I23: Female | J23: {=_xlfn.IFS(K23<30,"Young Adult",K23<=50,"Adult",K23>50,"Senior")} -> Senior | K23: 61 | L23: Clothing | M23: 4 | N23: 25 | O23: =M23 * N23 -> 100 | P23: =O23*$S$3 -> 1.5 | Q23: =O23*$S$4 -> 2 | R23: Avg Comm 2024 | S23: =AVERAGE(Q:Q) -> 9.12
A24: 678 | B24: =DAY(G24) -> 23 | C24: =MONTH(G24) -> 12 | D24: =YEAR(G24) -> 2023 | E24: =TEXT(G24,"dddd") -> Saturday | F24: =TEXT(G24,"mmm") -> Dec | G24: 45283 | H24: CUST678 | I24: Female | J24: {=_xlfn.IFS(K24<30,"Young Adult",K24<=50,"Adult",K24>50,"Senior")} -> Senior | K24: 60 | L24: Electronics | M24: 3 | N24: 300 | O24: =M24 * N24 -> 900 | P24: =O24*$S$3 -> 13.5 | Q24: =O24*$S$4 -> 18
A25: 781 | B25: =DAY(G25) -> 23 | C25: =MONTH(G25) -> 12 | D25: =YEAR(G25) -> 2023 | E25: =TEXT(G25,"dddd") -> Saturday | F25: =TEXT(G25,"mmm") -> Dec | G25: 45283 | H25: CUST781 | I25: Male | J25: {=_xlfn.IFS(K25<30,"Young Adult",K25<=50,"Adult",K25>50,"Senior")} -> Adult | K25: 35 | L25: Beauty | M25: 1 | N25: 500 | O25: =M25 * N25 -> 500 | P25: =O25*$S$3 -> 7.5 | Q25: =O25*$S$4 -> 10
A26: 544 | B26: =DAY(G26) -> 23 | C26: =MONTH(G26) -> 12 | D26: =YEAR(G26) -> 2023 | E26: =TEXT(G26,"dddd") -> Saturday | F26: =TEXT(G26,"mmm") -> Dec | G26: 45283 | H26: CUST544 | I26: Female | J26: {=_xlfn.IFS(K26<30,"Young Adult",K26<=50,"Adult",K26>50,"Senior")} -> Young Adult | K26: 27 | L26: Electronics | M26: 1 | N26: 25 | O26: =M26 * N26 -> 25 | P26: =O26*$S$3 -> 0.375 | Q26: =O26*$S$4 -> 0.5
A27: 309 | B27: =DAY(G27) -> 23 | C27: =MONTH(G27) -> 12 | D27: =YEAR(G27) -> 2023 | E27: =TEXT(G27,"dddd") -> Saturday | F27: =TEXT(G27,"mmm") -> Dec | G27: 45283 | H27: CUST309 | I27: Female | J27: {=_xlfn.IFS(K27<30,"Young Adult",K27<=50,"Adult",K27>50,"Senior")} -> Young Adult | K27: 26 | L27: Beauty | M27: 1 | N27: 25 | O27: =M27 * N27 -> 25 | P27: =O27*$S$3 -> 0.375 | Q27: =O27*$S$4 -> 0.5
A28: 602 | B28: =DAY(G28) -> 23 | C28: =MONTH(G28) -> 12 | D28: =YEAR(G28) -> 2023 | E28: =TEXT(G28,"dddd") -> Saturday | F28: =TEXT(G28,"mmm") -> Dec | G28: 45283 | H28: CUST602 | I28: Female | J28: {=_xlfn.IFS(K28<30,"Young Adult",K28<=50,"Adult",K28>50,"Senior")} -> Young Adult | K28: 20 | L28: Electronics | M28: 1 | N28: 300 | O28: =M28 * N28 -> 300 | P28: =O28*$S$3 -> 4.5 | Q28: =O28*$S$4 -> 6
A29: 662 | B29: =DAY(G29) -> 22 | C29: =MONTH(G29) -> 12 | D29: =YEAR(G29) -> 2023 | E29: =TEXT(G29,"dddd") -> Friday | F29: =TEXT(G29,"mmm") -> Dec | G29: 45282 | H29: CUST662 | I29: Male | J29: {=_xlfn.IFS(K29<30,"Young Adult",K29<=50,"Adult",K29>50,"Senior")} -> Adult | K29: 48 | L29: Beauty | M29: 2 | N29: 500 | O29: =M29 * N29 -> 1000 | P29: =O29*$S$3 -> 15 | Q29: =O29*$S$4 -> 20
A30: 865 | B30: =DAY(G30) -> 21 | C30: =MONTH(G30) -> 12 | D30: =YEAR(G30) -> 2023 | E30: =TEXT(G30,"dddd") -> Thursday | F30: =TEXT(G30,"mmm") -> Dec | G30: 45281 | H30: CUST865 | I30: Female | J30: {=_xlfn.IFS(K30<30,"Young Adult",K30<=50,"Adult",K30>50,"Senior")} -> Adult | K30: 42 | L30: Clothing | M30: 1 | N30: 300 | O30: =M30 * N30 -> 300 | P30: =O30*$S$3 -> 4.5 | Q30: =O30*$S$4 -> 6
A31: 777 | B31: =DAY(G31) -> 20 | C31: =MONTH(G31) -> 12 | D31: =YEAR(G31) -> 2023 | E31: =TEXT(G31,"dddd") -> Wednesday | F31: =TEXT(G31,"mmm") -> Dec | G31: 45280 | H31: CUST777 | I31: Male | J31: {=_xlfn.IFS(K31<30,"Young Adult",K31<=50,"Adult",K31>50,"Senior")} -> Adult | K31: 48 | L31: Electronics | M31: 3 | N31: 50 | O31: =M31 * N31 -> 150 | P31: =O31*$S$3 -> 2.25 | Q31: =O31*$S$4 -> 3
A32: 890 | B32: =DAY(G32) -> 20 | C32: =MONTH(G32) -> 12 | D32: =YEAR(G32) -> 2023 | E32: =TEXT(G32,"dddd") -> Wednesday | F32: =TEXT(G32,"mmm") -> Dec | G32: 45280 | H32: CUST890 | I32: Male | J32: {=_xlfn.IFS(K32<30,"Young Adult",K32<=50,"Adult",K32>50,"Senior")} -> Adult | K32: 34 | L32: Electronics | M32: 2 | N32: 25 | O32: =M32 * N32 -> 50 | P32: =O32*$S$3 -> 0.75 | Q32: =O32*$S$4 -> 1
A33: 209 | B33: =DAY(G33) -> 20 | C33: =MONTH(G33) -> 12 | D33: =YEAR(G33) -> 2023 | E33: =TEXT(G33,"dddd") -> Wednesday | F33: =TEXT(G33,"mmm") -> Dec | G33: 45280 | H33: CUST209 | I33: Female | J33: {=_xlfn.IFS(K33<30,"Young Adult",K33<=50,"Adult",K33>50,"Senior")} -> Adult | K33: 30 | L33: Electronics | M33: 4 | N33: 50 | O33: =M33 * N33 -> 200 | P33: =O33*$S$3 -> 3 | Q33: =O33*$S$4 -> 4
A34: 435 | B34: =DAY(G34) -> 20 | C34: =MONTH(G34) -> 12 | D34: =YEAR(G34) -> 2023 | E34: =TEXT(G34,"dddd") -> Wednesday | F34: =TEXT(G34,"mmm") -> Dec | G34: 45280 | H34: CUST435 | I34: Female | J34: {=_xlfn.IFS(K34<30,"Young Adult",K34<=50,"Adult",K34>50,"Senior")} -> Adult | K34: 30 | L34: Beauty | M34: 3 | N34: 300 | O34: =M34 * N34 -> 900 | P34: =O34*$S$3 -> 13.5 | Q34: =O34*$S$4 -> 18
A35: 854 | B35: =DAY(G35) -> 20 | C35: =MONTH(G35) -> 12 | D35: =YEAR(G35) -> 2023 | E35: =TEXT(G35,"dddd") -> Wednesday | F35: =TEXT(G35,"mmm") -> Dec | G35: 45280 | H35: CUST854 | I35: Male | J35: {=_xlfn.IFS(K35<30,"Young Adult",K35<=50,"Adult",K35>50,"Senior")} -> Young Adult | K35: 29 | L35: Clothing | M35: 1 | N35: 50 | O35: =M35 * N35 -> 50 | P35: =O35*$S$3 -> 0.75 | Q35: =O35*$S$4 -> 1
... A110: 171 | B110: =DAY(G110) -> 24 | C110: =MONTH(G110) -> 11 | D110: =YEAR(G110) -> 2023 | E110: =TEXT(G110,"dddd") -> Friday | F110: =TEXT(G110,"mmm") -> Nov | G110: 45254 | H110: CUST171 | I110: Female | J110: {=_xlfn.IFS(K110<30,"Young Adult",K110<=50,"Adult",K110>50,"Senior")} -> Senior | K110: 52 | L110: Clothing | M110: 3 | N110: 300 | O110: =M110 * N110 -> 900 | P110: =O110*$S$3 -> 13.5 | Q110: =O110*$S$4 -> 18
A111: 1 | B111: =DAY(G111) -> 24 | C111: =MONTH(G111) -> 11 | D111: =YEAR(G111) -> 2023 | E111: =TEXT(G111,"ddd") -> Fri | F111: =TEXT(G111,"mmm") -> Nov | G111: 45254 | H111: CUST001 | I111: Male | J111: {=_xlfn.IFS(K111<30,"Young Adult",K111<=50,"Adult",K111>50,"Senior")} -> Adult | K111: 34 | L111: Beauty | M111: 3 | N111: 50 | O111: =M111 * N111 -> 150 | P111: =O111*$S$3 -> 2.25 | Q111: =O111*$S$4 -> 3
A112: 95 | B112: =DAY(G112) -> 24 | C112: =MONTH(G112) -> 11 | D112: =YEAR(G112) -> 2023 | E112: =TEXT(G112,"dddd") -> Friday | F112: =TEXT(G112,"mmm") -> Nov | G112: 45254 | H112: CUST095 | I112: Female | J112: {=_xlfn.IFS(K112<30,"Young Adult",K112<=50,"Adult",K112>50,"Senior")} -> Adult | K112: 32 | L112: Clothing | M112: 2 | N112: 30 | O112: =M112 * N112 -> 60 | P112: =O112*$S$3 -> 0.9 | Q112: =O112*$S$4 -> 1.2
A113: 424 | B113: =DAY(G113) -> 23 | C113: =MONTH(G113) -> 11 | D113: =YEAR(G113) -> 2023 | E113: =TEXT(G113,"dddd") -> Thursday | F113: =TEXT(G113,"mmm") -> Nov | G113: 45253 | H113: CUST424 | I113: Male | J113: {=_xlfn.IFS(K113<30,"Young Adult",K113<=50,"Adult",K113>50,"Senior")} -> Senior | K113: 57 | L113: Beauty | M113: 4 | N113: 300 | O113: =M113 * N113 -> 1200 | P113: =O113*$S$3 -> 18 | Q113: =O113*$S$4 -> 24
A114: 918 | B114: =DAY(G114) -> 23 | C114: =MONTH(G114) -> 11 | D114: =YEAR(G114) -> 2023 | E114: =TEXT(G114,"dddd") -> Thursday | F114: =TEXT(G114,"mmm") -> Nov | G114: 45253 | H114: CUST918 | I114: Female | J114: {=_xlfn.IFS(K114<30,"Young Adult",K114<=50,"Adult",K114>50,"Senior")} -> Adult | K114: 42 | L114: Electronics | M114: 3 | N114: 30 | O114: =M114 * N114 -> 90 | P114: =O114*$S$3 -> 1.35 | Q114: =O114*$S$4 -> 1.8
...

Sheet Transactions
A1: Transaction ID | B1: Total Sales | C1: Product category | D1: Concatenate
A2: 10 | B2: =VLOOKUP(A2,retail_sales_dataset!A1:Q1001,15,FALSE) -> 200 | C2: {=VLOOKUP(A2,retail_sales_dataset!A1:Q1001,COLUMN(retail_sales_dataset!L:L),FALSE)} -> Clothing | D2: =CONCATENATE(B2," ",C2) -> 200 Clothing
A3: 15 | B3: {=VLOOKUP(A3,retail_sales_dataset!A1:Q1001,COLUMN(retail_sales_dataset!O:O),FALSE)} -> 2000 | C3: {=VLOOKUP(A3,retail_sales_dataset!A2:Q1002,COLUMN(retail_sales_dataset!L:L),FALSE)} -> Electronics
A4: 25 | B4: {=VLOOKUP(A4,retail_sales_dataset!A2:Q1002,COLUMN(retail_sales_dataset!O:O),FALSE)} -> 50 | C4: {=VLOOKUP(A4,retail_sales_dataset!A3:Q1003,COLUMN(retail_sales_dataset!L:L),FALSE)} -> Beauty
A5: 30 | B5: {=VLOOKUP(A5,retail_sales_dataset!A3:Q1003,COLUMN(retail_sales_dataset!O:O),FALSE)} -> 900 | C5: {=VLOOKUP(A5,retail_sales_dataset!A4:Q1004,COLUMN(retail_sales_dataset!L:L),FALSE)} -> Beauty
A6: 54 | B6: {=VLOOKUP(A6,retail_sales_dataset!A4:Q1004,COLUMN(retail_sales_dataset!O:O),FALSE)} -> 1500 | C6: {=VLOOKUP(A6,retail_sales_dataset!A5:Q1005,COLUMN(retail_sales_dataset!L:L),FALSE)} -> Electronics
A7: 55 | B7: {=VLOOKUP(A7,retail_sales_dataset!A5:Q1005,COLUMN(retail_sales_dataset!O:O),FALSE)} -> 120 | C7: {=VLOOKUP(A7,retail_sales_dataset!A6:Q1006,COLUMN(retail_sales_dataset!L:L),FALSE)} -> Beauty
A8: 67 | B8: {=VLOOKUP(A8,retail_sales_dataset!A6:Q1006,COLUMN(retail_sales_dataset!O:O),FALSE)} -> 1200 | C8: {=VLOOKUP(A8,retail_sales_dataset!A7:Q1007,COLUMN(retail_sales_dataset!L:L),FALSE)} -> Beauty
A9: 89 | B9: {=VLOOKUP(A9,retail_sales_dataset!A7:Q1007,COLUMN(retail_sales_dataset!O:O),FALSE)} -> 2000 | C9: {=VLOOKUP(A9,retail_sales_dataset!A8:Q1008,COLUMN(retail_sales_dataset!L:L),FALSE)} -> Electronics
A10: 100 | B10: {=VLOOKUP(A10,retail_sales_dataset!A8:Q1008,COLUMN(retail_sales_dataset!O:O),FALSE)} -> 30 | C10: {=VLOOKUP(A10,retail_sales_dataset!A9:Q1009,COLUMN(retail_sales_dataset!L:L),FALSE)} -> Electronics

Sheet Day 2 Task 2
A1: Student name | B1: English | C1: Mathematics | D1: Science | E1: Average | F1: Highest score
A2: Carol | B2: 75 | C2: 85 | D2: 85 | E2: =AVERAGE(B2:D2) -> 81.666667 | F2: =MAX(B2:D2) -> 85
A3: Ted | B3: 80 | C3: 75 | D3: 90 | E3: =AVERAGE(B3:D3) -> 81.666667 | F3: =MAX(B3:D3) -> 90
A4: Khan | B4: 85 | C4: 75 | D4: 80 | E4: =AVERAGE(B4:D4) -> 80 | F4: =MAX(B4:D4) -> 85
A5: Harry | B5: 80 | C5: 70 | D5: 80 | E5: =AVERAGE(B5:D5) -> 76.666667 | F5: =MAX(B5:D5) -> 80
A6: Sarah | B6: 80 | C6: 70 | D6: 80 | E6: =AVERAGE(B6:D6) -> 76.666667 | F6: =MAX(B6:D6) -> 80
A7: John | B7: 65 | C7: 80 | D7: 70 | E7: =AVERAGE(B7:D7) -> 71.666667 | F7: =MAX(B7:D7) -> 80
A8: Linda | B8: 90 | C8: 50 | D8: 70 | E8: =AVERAGE(B8:D8) -> 70 | F8: =MAX(B8:D8) -> 90
A9: Edward | B9: 55 | C9: 80 | D9: 60 | E9: =AVERAGE(B9:D9) -> 65 | F9: =MAX(B9:D9) -> 80
A10: Mary | B10: 55 | C10: 70 | D10: 65 | E10: =AVERAGE(B10:D10) -> 63.333333 | F10: =MAX(B10:D10) -> 70
A11: Thomas | B11: 55 | C11: 30 | D11: 65 | E11: =AVERAGE(B11:D11) -> 50 | F11: =MAX(B11:D11) -> 65
A14: Task
A15: 1) Apply filter and sorting to show the best students in each subject.
A16: 2) Calculate the average for all students and fill into Column E. (Use formula)
A17: 3) Using the =MAX fucntion, tell me what the students highest score was in column F.
A18: 4) Apply filter and sorting to show the best student in this classroom by average.
A19: 5) Apply filter and sorting to show the best student in this classroom by highest score.
A20: 6) Use conditional formatting to clearly identify the highest and lowest average scores
